Workbook

Sheet General
A1: Columna 1 | B1: ENERO | C1: FEBRERO | D1: MARZO | E1: ABRIL | F1: MAYO | G1: JUNIO | H1: JULIO | I1: AGOSTO | J1: SEPTIEMBRE | K1: OCTUBRE | L1: NOVIEMBRE | M1: DICIEMBRE | N1: TOTAL
A2: 2025 | B2: =SUM('Lista gastos'!E154:G168) -> 693.16 | C2: =SUM('Lista gastos'!E9:E20) -> 330.98 | D2: =SUM('Lista gastos'!E21:E30) -> 257.81 | E2: =SUM('Lista gastos'!E31:E45) -> 250.82 | F2: =SUM('Lista gastos'!E46:E60) -> 871.61 | G2: =SUM('Lista gastos'!E61:E74) -> 540.83 | H2: =SUM('Lista gastos'!E75:E87) -> 451.72 | I2: =SUM('Lista gastos'!E88:E97) -> 305.17 | J2: =SUM('Lista gastos'!E98:G111) -> 517.02 | K2: =SUM('Lista gastos'!E112:G122) -> 396.93 | L2: =SUM('Lista gastos'!E123:G134) -> 387.94 | M2: =SUM('Lista gastos'!E135:G154) -> 343.53 | N2: =SUM(B2:M2) -> 5347.52
A3: 2026 | B3: =SUM('Lista gastos'!E155:E169) -> 703.66 | C3: =SUM('Lista gastos'!E170:E180) -> 239.14 | D3: =SUM('Lista gastos'!E181:E194) -> 293.34 | E3: =SUM('Lista gastos'!E195:E211) -> 492.53 | F3: =SUM('Lista gastos'!E212:E224) -> 313.38 | G3: =SUM('Lista gastos'!E225:E247) -> 751.23 | H3: 0 | I3: 0 | J3: 0 | K3: 0 | L3: 0 | M3: 0 | N3: =SUM(B3:M3) -> 2793.28

Sheet Lista gastos
A1: AÑO | B1: FECHA | C1: Column 6 | D1: CONCEPTO | E1: DINERO | F1: CATEGORIA
A2: 2025 | B2: 45659 | D2: Gasolina | E2: 59.36 | F2: Coche
A3: 2025 | B3: 45660 | D3: Crosfit | E3: 55 | F3: Ejercicio
A4: 2025 | B4: 45664 | D4: Discord | E4: 71.44 | F4: Discord
A5: 2025 | B5: 45669 | D5: Microfono | E5: 23.99 | F5: Discord
A6: 2025 | B6: 45669 | D6: Cine y cena | E6: 32.5 | F6: Ocio
A7: 2025 | B7: 45676 | D7: Cena | E7: 15.5 | F7: Comida
A8: 2025 | B8: 45688 | D8: Champu | E8: 3.99 | F8: Aseo
A9: 2025 | B9: 45689 | D9: Gasolina | E9: 69.74 | F9: Coche | H9: =SUM(E2:E198) -> 6295.63
A10: 2025 | B10: 45689 | D10: Cena | E10: 14.3 | F10: Comida
A11: 2025 | B11: 45693 | D11: Trail | E11: 24 | F11: Ejercicio
A12: 2025 | B12: 45693 | D12: Crosfit | E12: 55 | F12: Ejercicio
A13: 2025 | B13: 45698 | D13: Champu | E13: 29.65 | F13: Aseo
A14: 2025 | B14: 45707 | D14: Medicamento | E14: 20.2 | F14: Medicamento
A15: 2025 | B15: 45712 | D15: Piscina del sabado | E15: 7 | F15: Ocio
A16: 2025 | B16: 45712 | D16: Gasolina | E16: 29.44 | F16: Coche
A17: 2025 | B17: 45712 | D17: Cena del domingo en ponys burgos | E17: 25.2 | F17: Comida
A18: 2025 | B18: 45712 | D18: Champu comprado por amazon | E18: 20.2 | F18: Aseo
A19: 2025 | B19: 45712 | D19: Cesta para setas comprada en Burgos y que se encuentra en el piso de Esther | E19: 21.95 | F19: Ocio
A20: 2025 | B20: 45715 | D20: Cena del sabado dia 22 despues de la piscina | E20: 14.3 | F20: Ocio
A21: 2025 | B21: 45722 | D21: Gasolina | E21: 39.22 | F21: Coche
... A63: 2025 | B63: 45815 | D63: Bizum a Ruben: zumo de naranja | E63: 2.8 | F63: Ocio
A64: 2025 | D64: museo | E64: 2 | F64: Ocio
A65: 2025 | D65: hamburguesa | E65: 12.95 | F65: Ocio
A66: 2025 | E66: 25.11
A67: 2025 | D67: bizum a Juanjo para la comida de navidad | E67: 28 | F67: Trabajo
A68: 2025 | B68: 45828 | D68: netflix | E68: 6.99 | F68: Ocio
A69: 2025 | B69: 45830 | D69: cine | E69: 18.8 | F69: Ocio
A70: 2025 | B70: 45831 | D70: Gasolina | E70: 46.89 | F70: Coche
A71: 2025 | B71: 45832 | D71: evernote | E71: 118.25 | F71: Trabajo
A72: 2025 | B72: 45832 | D72: Pincha peces | E72: 15 | F72: Ocio
A73: 2025 | B73: 45838 | D73: Hacienda | E73: 205.6 | F73: hacienda
A74: 2025 | B74: 45807 | D74: pastillas para las perras | E74: 14 | F74: Medicamento
A75: 2025 | B75: 45839 | D75: Gasolina | E75: 44.57 | F75: Coche
A76: 2025 | B76: 45839 | D76: Reparacion pc | E76: 145 | F76: Trabajo
A77: 2025 | B77: 45845 | D77: Compras barbacoa y casa | E77: 74.45 | F77: Comida
A78: 2025 | B78: 45849 | D78: Comida | E78: 7.2 | F78: Comida
A79: 2025 | B79: 45851 | D79: Gasolina | E79: 30 | F79: Coche
... A227: 2026 | B227: 46172 | D227: comida | E227: 12 | F227: Comida
A228: 2026 | B228: 46183 | D228: comida | E228: 10.3 | F228: Comida | G228: 46197 | H228: 99 evernote
...

Sheet Tabla dinámica 1
